<?xml version="1.0" ?>
<!-- This file was generated by robot assembler -->
<robot xmlns:xacro="http://ros.org/wiki/xacro">
  <xacro:macro name="gazebo_link_reference" params="link_name mu1:=0.9 mu2:=0.9" >
    <gazebo reference="${link_name}">
      <mu1>${mu1}</mu1>
      <mu2>${mu2}</mu2>
    </gazebo>
  </xacro:macro>
  <xacro:macro name="gazebo_transmission" params="joint_name" >
    <transmission name="${joint_name}_trans">
      <type>transmission_interface/SimpleTransmission</type>
      <joint name="${joint_name}">
        <hardwareInterface>hardware_interface/VelocityJointInterface</hardwareInterface>
        <!--hardwareInterface>hardware_interface/EffortJointInterface</hardwareInterface-->
      </joint>
      <actuator name="${joint_name}_motor">
        <hardwareInterface>hardware_interface/VelocityJointInterface</hardwareInterface>
        <!--hardwareInterface>hardware_interface/EffortJointInterface</hardwareInterface-->
        <mechanicalReduction>1</mechanicalReduction>
      </actuator>
    </transmission>
  </xacro:macro>

  <xacro:macro name="no_gazebo_transmission" params="joint_name" >
    <!-- dummy for fixed joint -->
  </xacro:macro>

  <xacro:macro name="pan_tilt_robot"
               params="prefix" >
    <!-- from robot_assembler -->
    <xacro:gazebo_link_reference link_name="${prefix}BASE" />
    <link name="${prefix}BASE">
      <inertial>
        <mass value="0.112"/>
        <origin rpy="0 0 0" xyz="-2.187035e-19 -0.012536 -0.000367"/>
        <inertia ixx="3.737235e-05" ixy="-1.093518e-22" ixz="-1.117885e-21" iyy="2.575474e-05" iyz="-9.334821e-07" izz="2.726761e-05"/>
      </inertial>
      <visual>
        <origin xyz="0.000000 0.000000 0.000000" rpy="0.00000000 -0.00000000 0.00000000"/>
        <geometry>
          <mesh filename="package://ur_e_description/pan_tilt/meshes/xm430_dynamixel.dae" scale="1.000000 1.000000 1.000000"/>
        </geometry>
      </visual>
      <collision>
        <origin xyz="0.000000 0.000000 0.000000" rpy="0.00000000 -0.00000000 0.00000000"/>
        <geometry>
          <mesh filename="package://ur_e_description/pan_tilt/meshes/xm430_dynamixel.dae" scale="1.000000 1.000000 1.000000"/>
        </geometry>
      </collision>
      <visual>
        <origin xyz="-0.000000 -0.000000 -0.003000" rpy="-1.57079633 0.00000000 3.14159265"/>
        <geometry>
          <mesh filename="package://ur_e_description/pan_tilt/meshes/fr12_x102.dae" scale="1.000000 1.000000 1.000000"/>
        </geometry>
      </visual>
      <collision>
        <origin xyz="-0.000000 -0.000000 -0.003000" rpy="-1.57079633 0.00000000 3.14159265"/>
        <geometry>
          <mesh filename="package://ur_e_description/pan_tilt/meshes/fr12_x102.dae" scale="1.000000 1.000000 1.000000"/>
        </geometry>
      </collision>
    </link>
    <xacro:gazebo_link_reference link_name="${prefix}LINK0" />
    <link name="${prefix}LINK0">
      <inertial>
        <mass value="0.015"/>
        <origin rpy="0 0 0" xyz="0.0 0.01345 -0.019"/>
        <inertia ixx="1.969763e-06" ixy="0.0" ixz="0.0" iyy="3.012500e-06" iyz="9.466331e-38" izz="3.159763e-06"/>
      </inertial>
      <visual>
        <origin xyz="0.000000 0.000000 -0.019000" rpy="0.00000000 1.57079633 0.00000000"/>
        <geometry>
          <mesh filename="package://ur_e_description/pan_tilt/meshes/fr12_h101s.dae" scale="1.000000 1.000000 1.000000"/>
        </geometry>
      </visual>
      <collision>
        <origin xyz="0.000000 0.000000 -0.019000" rpy="0.00000000 1.57079633 0.00000000"/>
        <geometry>
          <mesh filename="package://ur_e_description/pan_tilt/meshes/fr12_h101s.dae" scale="1.000000 1.000000 1.000000"/>
        </geometry>
      </collision>
    </link>
    <xacro:gazebo_transmission joint_name="${prefix}JOINT0" />
    <joint name="${prefix}JOINT0" type="revolute">
      <parent link="${prefix}BASE"/>
      <child  link="${prefix}LINK0"/>
      <origin xyz="0.000000 0.000000 0.019000" rpy="0.00000000 -0.00000000 0.00000000"/>
      <axis xyz="0 0 1"/>
      <limit effort="200" lower="-3.14159" upper="3.14159" velocity="40"/>
    </joint>

    <xacro:gazebo_link_reference link_name="${prefix}BASE" />
    <link name="${prefix}PAN_BASE">
      <inertial>
        <mass value="0.1"/>
        <origin rpy="0 0 0" xyz="0.0 -0.012 0.0015"/>
        <inertia ixx="3.202708e-05" ixy="0.0" ixz="0.0" iyy="2.077708e-05" iyz="3.549874e-37" izz="2.478750e-05"/>
      </inertial>
      <visual>
        <origin xyz="0.000000 0.000000 0.000000" rpy="0.00000000 -0.00000000 0.00000000"/>
        <geometry>
          <mesh filename="package://ur_e_description/pan_tilt/meshes/xm430_dynamixel.dae" scale="1.000000 1.000000 1.000000"/>
        </geometry>
      </visual>
      <collision>
        <origin xyz="0.000000 0.000000 0.000000" rpy="0.00000000 -0.00000000 0.00000000"/>
        <geometry>
          <mesh filename="package://ur_e_description/pan_tilt/meshes/xm430_dynamixel.dae" scale="1.000000 1.000000 1.000000"/>
        </geometry>
      </collision>
    </link>
    <xacro:gazebo_link_reference link_name="${prefix}LINK1" />
    <link name="${prefix}LINK1">
      <inertial>
        <mass value="0.015"/>
        <origin rpy="0 0 0" xyz="-0.01345 9.706125e-18 -0.019"/>
        <inertia ixx="3.012500e-06" ixy="-7.524859e-22" ixz="-9.466331e-38" iyy="1.969763e-06" iyz="8.407791e-53" izz="3.159763e-06"/>
      </inertial>
      <visual>
        <origin xyz="0.000000 0.000000 -0.019000" rpy="0.00000000 1.57079633 1.57079633"/>
        <geometry>
          <mesh filename="package://ur_e_description/pan_tilt/meshes/fr12_h101.dae" scale="1.000000 1.000000 1.000000"/>
        </geometry>
      </visual>
      <collision>
        <origin xyz="0.000000 0.000000 -0.019000" rpy="0.00000000 1.57079633 1.57079633"/>
        <geometry>
          <mesh filename="package://ur_e_description/pan_tilt/meshes/fr12_h101.dae" scale="1.000000 1.000000 1.000000"/>
        </geometry>
      </collision>
    </link>
    <xacro:gazebo_transmission joint_name="${prefix}JOINT1" />
    <joint name="${prefix}JOINT1" type="revolute">
      <parent link="${prefix}PAN_BASE"/>
      <child  link="${prefix}LINK1"/>
      <origin xyz="0.000000 0.000000 0.019000" rpy="0.00000000 -0.00000000 0.00000000"/>
      <axis xyz="0 0 1"/>
      <limit effort="200" lower="-3.14159" upper="3.14159" velocity="40"/>
    </joint>

    <joint name="${prefix}tilt_to_pan" type="fixed" >
      <parent link="${prefix}LINK0"/>
      <child  link="${prefix}PAN_BASE"/>
      <origin xyz="0.0 0.0 0.016" rpy="0.0 1.57079633 0.0"/>
    </joint>
  </xacro:macro>

</robot>
