<?xml version="1.0" ?>
<!-- =================================================================================== -->
<!-- |    This document was autogenerated by xacro from urdf/dual_ur5e_robot.urdf.xacro | -->
<!-- |    EDITING THIS FILE BY HAND IS NOT RECOMMENDED                                 | -->
<!-- =================================================================================== -->
<robot name="dual_ur5e" xmlns:xacro="http://ros.org/wiki/xacro">
  <gazebo>
    <plugin filename="libgazebo_ros_control.so" name="ros_control">
      <!--robotNamespace>/</robotNamespace-->
      <!--robotSimType>gazebo_ros_control/DefaultRobotHWSim</robotSimType-->
    </plugin>
    <!--
    <plugin name="gazebo_ros_power_monitor_controller" filename="libgazebo_ros_power_monitor.so">
      <alwaysOn>true</alwaysOn>
      <updateRate>1.0</updateRate>
      <timeout>5</timeout>
      <powerStateTopic>power_state</powerStateTopic>
      <powerStateRate>10.0</powerStateRate>
      <fullChargeCapacity>87.78</fullChargeCapacity>     
      <dischargeRate>-474</dischargeRate>
      <chargeRate>525</chargeRate>
      <dischargeVoltage>15.52</dischargeVoltage>
      <chargeVoltage>16.41</chargeVoltage>
    </plugin>
-->
  </gazebo>
  <!--property name="shoulder_height" value="0.089159" /-->
  <!--property name="shoulder_offset" value="0.13585" /-->
  <!-- shoulder_offset - elbow_offset + wrist_1_length = 0.10915 -->
  <!--property name="upper_arm_length" value="0.42500" /-->
  <!--property name="elbow_offset" value="0.1197" /-->
  <!-- CAD measured -->
  <!--property name="forearm_length" value="0.39225" /-->
  <!--property name="wrist_1_length" value="0.093" /-->
  <!-- CAD measured -->
  <!--property name="wrist_2_length" value="0.09465" /-->
  <!-- In CAD this distance is 0.930, but in the spec it is 0.09465 -->
  <!--property name="wrist_3_length" value="0.0823" /-->
  <!-- manually measured -->
  <link name="right_base_link">
    <visual>
      <geometry>
        <mesh filename="package://ur_e_description/meshes/ur5e/visual/base.dae"/>
      </geometry>
      <!--material name="LightGrey">
          <color rgba="0.7 0.7 0.7 1.0"/>
        </material-->
    </visual>
    <collision>
      <geometry>
        <mesh filename="package://ur_e_description/meshes/ur5e/collision/base.stl"/>
      </geometry>
    </collision>
    <inertial>
      <mass value="4.0"/>
      <origin rpy="0 0 0" xyz="0.0 0.0 0.0"/>
      <inertia ixx="0.00443333156" ixy="0.0" ixz="0.0" iyy="0.00443333156" iyz="0.0" izz="0.0072"/>
    </inertial>
  </link>
  <joint name="right_shoulder_pan_joint" type="revolute">
    <parent link="right_base_link"/>
    <child link="right_shoulder_link"/>
    <origin rpy="0.0 0.0 0.0" xyz="0.0 0.0 0.163"/>
    <axis xyz="0 0 1"/>
    <limit effort="150.0" lower="-3.14159265359" upper="3.14159265359" velocity="3.14"/>
    <dynamics damping="0.0" friction="0.0"/>
  </joint>
  <link name="right_shoulder_link">
    <visual>
      <geometry>
        <mesh filename="package://ur_e_description/meshes/ur5e/visual/shoulder.dae"/>
      </geometry>
      <!--material name="LightGrey">
          <color rgba="0.7 0.7 0.7 1.0"/>
        </material-->
    </visual>
    <collision>
      <geometry>
        <mesh filename="package://ur_e_description/meshes/ur5e/collision/shoulder.stl"/>
      </geometry>
    </collision>
    <inertial>
      <mass value="3.7"/>
      <origin rpy="0 0 0" xyz="0.0 0.0 0.0"/>
      <inertia ixx="0.010267495893" ixy="0.0" ixz="0.0" iyy="0.010267495893" iyz="0.0" izz="0.00666"/>
    </inertial>
  </link>
  <joint name="right_shoulder_lift_joint" type="revolute">
    <parent link="right_shoulder_link"/>
    <child link="right_upper_arm_link"/>
    <origin rpy="0.0 1.57079632679 0.0" xyz="0.0 0.138 0.0"/>
    <axis xyz="0 1 0"/>
    <limit effort="150.0" lower="0" upper="6.28318530718" velocity="3.14"/>
    <dynamics damping="0.0" friction="0.0"/>
  </joint>
  <link name="right_upper_arm_link">
    <visual>
      <geometry>
        <mesh filename="package://ur_e_description/meshes/ur5e/visual/upperarm.dae"/>
      </geometry>
      <!--material name="LightGrey">
          <color rgba="0.7 0.7 0.7 1.0"/>
        </material-->
    </visual>
    <collision>
      <geometry>
        <mesh filename="package://ur_e_description/meshes/ur5e/collision/upperarm.stl"/>
      </geometry>
    </collision>
    <inertial>
      <mass value="8.393"/>
      <origin rpy="0 0 0" xyz="0.0 0.0 0.2125"/>
      <inertia ixx="0.133885781862" ixy="0.0" ixz="0.0" iyy="0.133885781862" iyz="0.0" izz="0.0151074"/>
    </inertial>
  </link>
  <joint name="right_elbow_joint" type="revolute">
    <parent link="right_upper_arm_link"/>
    <child link="right_forearm_link"/>
    <origin rpy="0.0 0.0 0.0" xyz="0.0 -0.131 0.425"/>
    <axis xyz="0 1 0"/>
    <limit effort="150.0" lower="-3.14159265359" upper="3.14159265359" velocity="3.14"/>
    <dynamics damping="0.0" friction="0.0"/>
  </joint>
  <link name="right_forearm_link">
    <visual>
      <geometry>
        <mesh filename="package://ur_e_description/meshes/ur5e/visual/forearm.dae"/>
      </geometry>
      <!--material name="LightGrey">
          <color rgba="0.7 0.7 0.7 1.0"/>
        </material-->
    </visual>
    <collision>
      <geometry>
        <mesh filename="package://ur_e_description/meshes/ur5e/collision/forearm.stl"/>
      </geometry>
    </collision>
    <inertial>
      <mass value="2.275"/>
      <origin rpy="0 0 0" xyz="0.0 0.0 0.196"/>
      <inertia ixx="0.0311796208615" ixy="0.0" ixz="0.0" iyy="0.0311796208615" iyz="0.0" izz="0.004095"/>
    </inertial>
  </link>
  <joint name="right_wrist_1_joint" type="revolute">
    <parent link="right_forearm_link"/>
    <child link="right_wrist_1_link"/>
    <origin rpy="0.0 1.57079632679 0.0" xyz="0.0 0.0 0.392"/>
    <axis xyz="0 1 0"/>
    <limit effort="28.0" lower="0" upper="6.28318530718" velocity="6.28"/>
    <dynamics damping="0.0" friction="0.0"/>
  </joint>
  <link name="right_wrist_1_link">
    <visual>
      <geometry>
        <mesh filename="package://ur_e_description/meshes/ur5e/visual/wrist1.dae"/>
      </geometry>
      <!--material name="LightGrey">
          <color rgba="0.7 0.7 0.7 1.0"/>
        </material-->
    </visual>
    <collision>
      <geometry>
        <mesh filename="package://ur_e_description/meshes/ur5e/collision/wrist1.stl"/>
      </geometry>
    </collision>
    <inertial>
      <mass value="1.219"/>
      <origin rpy="0 0 0" xyz="0.0 0.127 0.0"/>
      <inertia ixx="0.00255989897604" ixy="0.0" ixz="0.0" iyy="0.00255989897604" iyz="0.0" izz="0.0021942"/>
    </inertial>
  </link>
  <joint name="right_wrist_2_joint" type="revolute">
    <parent link="right_wrist_1_link"/>
    <child link="right_wrist_2_link"/>
    <origin rpy="0.0 0.0 0.0" xyz="0.0 0.127 0.0"/>
    <axis xyz="0 0 1"/>
    <limit effort="28.0" lower="-3.14159265359" upper="3.14159265359" velocity="6.28"/>
    <dynamics damping="0.0" friction="0.0"/>
  </joint>
  <link name="right_wrist_2_link">
    <visual>
      <geometry>
        <mesh filename="package://ur_e_description/meshes/ur5e/visual/wrist2.dae"/>
      </geometry>
      <!--material name="LightGrey">
          <color rgba="0.7 0.7 0.7 1.0"/>
        </material-->
    </visual>
    <collision>
      <geometry>
        <mesh filename="package://ur_e_description/meshes/ur5e/collision/wrist2.stl"/>
      </geometry>
    </collision>
    <inertial>
      <mass value="1.219"/>
      <origin rpy="0 0 0" xyz="0.0 0.0 0.1"/>
      <inertia ixx="0.00255989897604" ixy="0.0" ixz="0.0" iyy="0.00255989897604" iyz="0.0" izz="0.0021942"/>
    </inertial>
  </link>
  <joint name="right_wrist_3_joint" type="revolute">
    <parent link="right_wrist_2_link"/>
    <child link="right_wrist_3_link"/>
    <origin rpy="0.0 0.0 0.0" xyz="0.0 0.0 0.1"/>
    <axis xyz="0 1 0"/>
    <limit effort="28.0" lower="-3.14159265359" upper="3.14159265359" velocity="6.28"/>
    <dynamics damping="0.0" friction="0.0"/>
  </joint>
  <link name="right_wrist_3_link">
    <visual>
      <geometry>
        <mesh filename="package://ur_e_description/meshes/ur5e/visual/wrist3.dae"/>
      </geometry>
      <!--material name="LightGrey">
          <color rgba="0.7 0.7 0.7 1.0"/>
        </material-->
    </visual>
    <collision>
      <geometry>
        <mesh filename="package://ur_e_description/meshes/ur5e/collision/wrist3.stl"/>
      </geometry>
    </collision>
    <inertial>
      <mass value="0.1879"/>
      <origin rpy="1.57079632679 0 0" xyz="0.0 0.0771 0.0"/>
      <inertia ixx="9.89041005217e-05" ixy="0.0" ixz="0.0" iyy="9.89041005217e-05" iyz="0.0" izz="0.0001321171875"/>
    </inertial>
  </link>
  <joint name="right_ee_fixed_joint" type="fixed">
    <parent link="right_wrist_3_link"/>
    <child link="right_ee_link"/>
    <origin rpy="0.0 0.0 1.57079632679" xyz="0.0 0.1 0.0"/>
  </joint>
  <link name="right_ee_link">
    <collision>
      <geometry>
        <box size="0.01 0.01 0.01"/>
      </geometry>
      <origin rpy="0 0 0" xyz="-0.01 0 0"/>
    </collision>
  </link>
  <transmission name="right_shoulder_pan_trans">
    <type>transmission_interface/SimpleTransmission</type>
    <joint name="right_shoulder_pan_joint">
      <hardwareInterface>hardware_interface/PositionJointInterface</hardwareInterface>
    </joint>
    <actuator name="right_shoulder_pan_motor">
      <mechanicalReduction>1</mechanicalReduction>
    </actuator>
  </transmission>
  <transmission name="right_shoulder_lift_trans">
    <type>transmission_interface/SimpleTransmission</type>
    <joint name="right_shoulder_lift_joint">
      <hardwareInterface>hardware_interface/PositionJointInterface</hardwareInterface>
    </joint>
    <actuator name="right_shoulder_lift_motor">
      <mechanicalReduction>1</mechanicalReduction>
    </actuator>
  </transmission>
  <transmission name="right_elbow_trans">
    <type>transmission_interface/SimpleTransmission</type>
    <joint name="right_elbow_joint">
      <hardwareInterface>hardware_interface/PositionJointInterface</hardwareInterface>
    </joint>
    <actuator name="right_elbow_motor">
      <mechanicalReduction>1</mechanicalReduction>
    </actuator>
  </transmission>
  <transmission name="right_wrist_1_trans">
    <type>transmission_interface/SimpleTransmission</type>
    <joint name="right_wrist_1_joint">
      <hardwareInterface>hardware_interface/PositionJointInterface</hardwareInterface>
    </joint>
    <actuator name="right_wrist_1_motor">
      <mechanicalReduction>1</mechanicalReduction>
    </actuator>
  </transmission>
  <transmission name="right_wrist_2_trans">
    <type>transmission_interface/SimpleTransmission</type>
    <joint name="right_wrist_2_joint">
      <hardwareInterface>hardware_interface/PositionJointInterface</hardwareInterface>
    </joint>
    <actuator name="right_wrist_2_motor">
      <mechanicalReduction>1</mechanicalReduction>
    </actuator>
  </transmission>
  <transmission name="right_wrist_3_trans">
    <type>transmission_interface/SimpleTransmission</type>
    <joint name="right_wrist_3_joint">
      <hardwareInterface>hardware_interface/PositionJointInterface</hardwareInterface>
    </joint>
    <actuator name="right_wrist_3_motor">
      <mechanicalReduction>1</mechanicalReduction>
    </actuator>
  </transmission>
  <gazebo reference="right_shoulder_link">
    <selfCollide>true</selfCollide>
  </gazebo>
  <gazebo reference="right_upper_arm_link">
    <selfCollide>true</selfCollide>
  </gazebo>
  <gazebo reference="right_forearm_link">
    <selfCollide>true</selfCollide>
  </gazebo>
  <gazebo reference="right_wrist_1_link">
    <selfCollide>true</selfCollide>
  </gazebo>
  <gazebo reference="right_wrist_3_link">
    <selfCollide>true</selfCollide>
  </gazebo>
  <gazebo reference="right_wrist_2_link">
    <selfCollide>true</selfCollide>
  </gazebo>
  <gazebo reference="right_ee_link">
    <selfCollide>true</selfCollide>
  </gazebo>
  <!-- ROS base_link to UR 'Base' Coordinates transform -->
  <link name="right_base"/>
  <joint name="right_base_link-base_fixed_joint" type="fixed">
    <!-- NOTE: this rotation is only needed as long as base_link itself is
                 not corrected wrt the real robot (ie: rotated over 180
                 degrees)
      -->
    <origin rpy="0 0 -3.14159265359" xyz="0 0 0"/>
    <parent link="right_base_link"/>
    <child link="right_base"/>
  </joint>
  <!-- Frame coincident with all-zeros TCP on UR controller -->
  <link name="right_tool0"/>
  <joint name="right_wrist_3_link-tool0_fixed_joint" type="fixed">
    <origin rpy="-1.57079632679 0 0" xyz="0 0.1 0"/>
    <parent link="right_wrist_3_link"/>
    <child link="right_tool0"/>
  </joint>
  <!--property name="shoulder_height" value="0.089159" /-->
  <!--property name="shoulder_offset" value="0.13585" /-->
  <!-- shoulder_offset - elbow_offset + wrist_1_length = 0.10915 -->
  <!--property name="upper_arm_length" value="0.42500" /-->
  <!--property name="elbow_offset" value="0.1197" /-->
  <!-- CAD measured -->
  <!--property name="forearm_length" value="0.39225" /-->
  <!--property name="wrist_1_length" value="0.093" /-->
  <!-- CAD measured -->
  <!--property name="wrist_2_length" value="0.09465" /-->
  <!-- In CAD this distance is 0.930, but in the spec it is 0.09465 -->
  <!--property name="wrist_3_length" value="0.0823" /-->
  <!-- manually measured -->
  <link name="left_base_link">
    <visual>
      <geometry>
        <mesh filename="package://ur_e_description/meshes/ur5e/visual/base.dae"/>
      </geometry>
      <!--material name="LightGrey">
          <color rgba="0.7 0.7 0.7 1.0"/>
        </material-->
    </visual>
    <collision>
      <geometry>
        <mesh filename="package://ur_e_description/meshes/ur5e/collision/base.stl"/>
      </geometry>
    </collision>
    <inertial>
      <mass value="4.0"/>
      <origin rpy="0 0 0" xyz="0.0 0.0 0.0"/>
      <inertia ixx="0.00443333156" ixy="0.0" ixz="0.0" iyy="0.00443333156" iyz="0.0" izz="0.0072"/>
    </inertial>
  </link>
  <joint name="left_shoulder_pan_joint" type="revolute">
    <parent link="left_base_link"/>
    <child link="left_shoulder_link"/>
    <origin rpy="0.0 0.0 0.0" xyz="0.0 0.0 0.163"/>
    <axis xyz="0 0 1"/>
    <limit effort="150.0" lower="-3.14159265359" upper="3.14159265359" velocity="3.14"/>
    <dynamics damping="0.0" friction="0.0"/>
  </joint>
  <link name="left_shoulder_link">
    <visual>
      <geometry>
        <mesh filename="package://ur_e_description/meshes/ur5e/visual/shoulder.dae"/>
      </geometry>
      <!--material name="LightGrey">
          <color rgba="0.7 0.7 0.7 1.0"/>
        </material-->
    </visual>
    <collision>
      <geometry>
        <mesh filename="package://ur_e_description/meshes/ur5e/collision/shoulder.stl"/>
      </geometry>
    </collision>
    <inertial>
      <mass value="3.7"/>
      <origin rpy="0 0 0" xyz="0.0 0.0 0.0"/>
      <inertia ixx="0.010267495893" ixy="0.0" ixz="0.0" iyy="0.010267495893" iyz="0.0" izz="0.00666"/>
    </inertial>
  </link>
  <joint name="left_shoulder_lift_joint" type="revolute">
    <parent link="left_shoulder_link"/>
    <child link="left_upper_arm_link"/>
    <origin rpy="0.0 1.57079632679 0.0" xyz="0.0 0.138 0.0"/>
    <axis xyz="0 1 0"/>
    <limit effort="150.0" lower="-3.14159265359" upper="3.14159265359" velocity="3.14"/>
    <dynamics damping="0.0" friction="0.0"/>
  </joint>
  <link name="left_upper_arm_link">
    <visual>
      <geometry>
        <mesh filename="package://ur_e_description/meshes/ur5e/visual/upperarm.dae"/>
      </geometry>
      <!--material name="LightGrey">
          <color rgba="0.7 0.7 0.7 1.0"/>
        </material-->
    </visual>
    <collision>
      <geometry>
        <mesh filename="package://ur_e_description/meshes/ur5e/collision/upperarm.stl"/>
      </geometry>
    </collision>
    <inertial>
      <mass value="8.393"/>
      <origin rpy="0 0 0" xyz="0.0 0.0 0.2125"/>
      <inertia ixx="0.133885781862" ixy="0.0" ixz="0.0" iyy="0.133885781862" iyz="0.0" izz="0.0151074"/>
    </inertial>
  </link>
  <joint name="left_elbow_joint" type="revolute">
    <parent link="left_upper_arm_link"/>
    <child link="left_forearm_link"/>
    <origin rpy="0.0 0.0 0.0" xyz="0.0 -0.131 0.425"/>
    <axis xyz="0 1 0"/>
    <limit effort="150.0" lower="-3.14159265359" upper="3.14159265359" velocity="3.14"/>
    <dynamics damping="0.0" friction="0.0"/>
  </joint>
  <link name="left_forearm_link">
    <visual>
      <geometry>
        <mesh filename="package://ur_e_description/meshes/ur5e/visual/forearm.dae"/>
      </geometry>
      <!--material name="LightGrey">
          <color rgba="0.7 0.7 0.7 1.0"/>
        </material-->
    </visual>
    <collision>
      <geometry>
        <mesh filename="package://ur_e_description/meshes/ur5e/collision/forearm.stl"/>
      </geometry>
    </collision>
    <inertial>
      <mass value="2.275"/>
      <origin rpy="0 0 0" xyz="0.0 0.0 0.196"/>
      <inertia ixx="0.0311796208615" ixy="0.0" ixz="0.0" iyy="0.0311796208615" iyz="0.0" izz="0.004095"/>
    </inertial>
  </link>
  <joint name="left_wrist_1_joint" type="revolute">
    <parent link="left_forearm_link"/>
    <child link="left_wrist_1_link"/>
    <origin rpy="0.0 1.57079632679 0.0" xyz="0.0 0.0 0.392"/>
    <axis xyz="0 1 0"/>
    <limit effort="28.0" lower="-3.14159265359" upper="3.14159265359" velocity="6.28"/>
    <dynamics damping="0.0" friction="0.0"/>
  </joint>
  <link name="left_wrist_1_link">
    <visual>
      <geometry>
        <mesh filename="package://ur_e_description/meshes/ur5e/visual/wrist1.dae"/>
      </geometry>
      <!--material name="LightGrey">
          <color rgba="0.7 0.7 0.7 1.0"/>
        </material-->
    </visual>
    <collision>
      <geometry>
        <mesh filename="package://ur_e_description/meshes/ur5e/collision/wrist1.stl"/>
      </geometry>
    </collision>
    <inertial>
      <mass value="1.219"/>
      <origin rpy="0 0 0" xyz="0.0 0.127 0.0"/>
      <inertia ixx="0.00255989897604" ixy="0.0" ixz="0.0" iyy="0.00255989897604" iyz="0.0" izz="0.0021942"/>
    </inertial>
  </link>
  <joint name="left_wrist_2_joint" type="revolute">
    <parent link="left_wrist_1_link"/>
    <child link="left_wrist_2_link"/>
    <origin rpy="0.0 0.0 0.0" xyz="0.0 0.127 0.0"/>
    <axis xyz="0 0 1"/>
    <limit effort="28.0" lower="-3.14159265359" upper="3.14159265359" velocity="6.28"/>
    <dynamics damping="0.0" friction="0.0"/>
  </joint>
  <link name="left_wrist_2_link">
    <visual>
      <geometry>
        <mesh filename="package://ur_e_description/meshes/ur5e/visual/wrist2.dae"/>
      </geometry>
      <!--material name="LightGrey">
          <color rgba="0.7 0.7 0.7 1.0"/>
        </material-->
    </visual>
    <collision>
      <geometry>
        <mesh filename="package://ur_e_description/meshes/ur5e/collision/wrist2.stl"/>
      </geometry>
    </collision>
    <inertial>
      <mass value="1.219"/>
      <origin rpy="0 0 0" xyz="0.0 0.0 0.1"/>
      <inertia ixx="0.00255989897604" ixy="0.0" ixz="0.0" iyy="0.00255989897604" iyz="0.0" izz="0.0021942"/>
    </inertial>
  </link>
  <joint name="left_wrist_3_joint" type="revolute">
    <parent link="left_wrist_2_link"/>
    <child link="left_wrist_3_link"/>
    <origin rpy="0.0 0.0 0.0" xyz="0.0 0.0 0.1"/>
    <axis xyz="0 1 0"/>
    <limit effort="28.0" lower="-3.14159265359" upper="3.14159265359" velocity="6.28"/>
    <dynamics damping="0.0" friction="0.0"/>
  </joint>
  <link name="left_wrist_3_link">
    <visual>
      <geometry>
        <mesh filename="package://ur_e_description/meshes/ur5e/visual/wrist3.dae"/>
      </geometry>
      <!--material name="LightGrey">
          <color rgba="0.7 0.7 0.7 1.0"/>
        </material-->
    </visual>
    <collision>
      <geometry>
        <mesh filename="package://ur_e_description/meshes/ur5e/collision/wrist3.stl"/>
      </geometry>
    </collision>
    <inertial>
      <mass value="0.1879"/>
      <origin rpy="1.57079632679 0 0" xyz="0.0 0.0771 0.0"/>
      <inertia ixx="9.89041005217e-05" ixy="0.0" ixz="0.0" iyy="9.89041005217e-05" iyz="0.0" izz="0.0001321171875"/>
    </inertial>
  </link>
  <joint name="left_ee_fixed_joint" type="fixed">
    <parent link="left_wrist_3_link"/>
    <child link="left_ee_link"/>
    <origin rpy="0.0 0.0 1.57079632679" xyz="0.0 0.1 0.0"/>
  </joint>
  <link name="left_ee_link">
    <collision>
      <geometry>
        <box size="0.01 0.01 0.01"/>
      </geometry>
      <origin rpy="0 0 0" xyz="-0.01 0 0"/>
    </collision>
  </link>
  <transmission name="left_shoulder_pan_trans">
    <type>transmission_interface/SimpleTransmission</type>
    <joint name="left_shoulder_pan_joint">
      <hardwareInterface>hardware_interface/PositionJointInterface</hardwareInterface>
    </joint>
    <actuator name="left_shoulder_pan_motor">
      <mechanicalReduction>1</mechanicalReduction>
    </actuator>
  </transmission>
  <transmission name="left_shoulder_lift_trans">
    <type>transmission_interface/SimpleTransmission</type>
    <joint name="left_shoulder_lift_joint">
      <hardwareInterface>hardware_interface/PositionJointInterface</hardwareInterface>
    </joint>
    <actuator name="left_shoulder_lift_motor">
      <mechanicalReduction>1</mechanicalReduction>
    </actuator>
  </transmission>
  <transmission name="left_elbow_trans">
    <type>transmission_interface/SimpleTransmission</type>
    <joint name="left_elbow_joint">
      <hardwareInterface>hardware_interface/PositionJointInterface</hardwareInterface>
    </joint>
    <actuator name="left_elbow_motor">
      <mechanicalReduction>1</mechanicalReduction>
    </actuator>
  </transmission>
  <transmission name="left_wrist_1_trans">
    <type>transmission_interface/SimpleTransmission</type>
    <joint name="left_wrist_1_joint">
      <hardwareInterface>hardware_interface/PositionJointInterface</hardwareInterface>
    </joint>
    <actuator name="left_wrist_1_motor">
      <mechanicalReduction>1</mechanicalReduction>
    </actuator>
  </transmission>
  <transmission name="left_wrist_2_trans">
    <type>transmission_interface/SimpleTransmission</type>
    <joint name="left_wrist_2_joint">
      <hardwareInterface>hardware_interface/PositionJointInterface</hardwareInterface>
    </joint>
    <actuator name="left_wrist_2_motor">
      <mechanicalReduction>1</mechanicalReduction>
    </actuator>
  </transmission>
  <transmission name="left_wrist_3_trans">
    <type>transmission_interface/SimpleTransmission</type>
    <joint name="left_wrist_3_joint">
      <hardwareInterface>hardware_interface/PositionJointInterface</hardwareInterface>
    </joint>
    <actuator name="left_wrist_3_motor">
      <mechanicalReduction>1</mechanicalReduction>
    </actuator>
  </transmission>
  <gazebo reference="left_shoulder_link">
    <selfCollide>true</selfCollide>
  </gazebo>
  <gazebo reference="left_upper_arm_link">
    <selfCollide>true</selfCollide>
  </gazebo>
  <gazebo reference="left_forearm_link">
    <selfCollide>true</selfCollide>
  </gazebo>
  <gazebo reference="left_wrist_1_link">
    <selfCollide>true</selfCollide>
  </gazebo>
  <gazebo reference="left_wrist_3_link">
    <selfCollide>true</selfCollide>
  </gazebo>
  <gazebo reference="left_wrist_2_link">
    <selfCollide>true</selfCollide>
  </gazebo>
  <gazebo reference="left_ee_link">
    <selfCollide>true</selfCollide>
  </gazebo>
  <!-- ROS base_link to UR 'Base' Coordinates transform -->
  <link name="left_base"/>
  <joint name="left_base_link-base_fixed_joint" type="fixed">
    <!-- NOTE: this rotation is only needed as long as base_link itself is
                 not corrected wrt the real robot (ie: rotated over 180
                 degrees)
      -->
    <origin rpy="0 0 -3.14159265359" xyz="0 0 0"/>
    <parent link="left_base_link"/>
    <child link="left_base"/>
  </joint>
  <!-- Frame coincident with all-zeros TCP on UR controller -->
  <link name="left_tool0"/>
  <joint name="left_wrist_3_link-tool0_fixed_joint" type="fixed">
    <origin rpy="-1.57079632679 0 0" xyz="0 0.1 0"/>
    <parent link="left_wrist_3_link"/>
    <child link="left_tool0"/>
  </joint>
  <link name="fixed_base"/>
  <joint name="left_fixed_base_joint" type="fixed">
    <parent link="fixed_base"/>
    <child link="left_base_link"/>
    <!--origin xyz="0.0  0.165 0.0" rpy="-2.35619449019234 0.0 0.0" /-->
    <!-- (send cds :rotate -pi/2 :x) (send cds :rotate (deg2rad -45) :x :world) / -45deg -->
    <origin rpy="-1.5707963267949 0.0 0.0" xyz="0.0  0.150 0.0"/>
    <!-- 0deg -->
    <!--origin xyz="0.0  0.165 0.0" rpy="-0.78539816339745 0.0 0.0" /-->
    <!-- 45deg -->
  </joint>
  <joint name="right_fixed_base_joint" type="fixed">
    <parent link="fixed_base"/>
    <child link="right_base_link"/>
    <!--origin xyz="0.0 -0.165 0.0" rpy="-2.35619449019234 0.0 3.14159265358979" /-->
    <!-- (send cds :rotate pi/2 :x) (send cds :rotate pi :y :world) (send cds :rotate (deg2rad  45) :x :world) / 45deg -->
    <origin rpy="-1.5707963267949 0.0 3.14159265358979" xyz="0.0 -0.150 0.0"/>
    <!-- 0deg -->
    <!--origin xyz="0.0 -0.165 0.0" rpy="-0.78539816339745 0.0 3.14159265358979" /-->
    <!-- 45deg -->
  </joint>
  <link name="dual_arm_base">
    <visual>
      <origin rpy="1.5707963267949 0.0 0.0" xyz="0 -0.4 0"/>
      <geometry>
        <mesh filename="package://ur_e_description/meshes/ur5e/dual_ur5_base.stl"/>
      </geometry>
      <material name="misumi">
        <color rgba="0.75 0.75 0.75 1.0"/>
      </material>
    </visual>
    <collision>
      <origin rpy="1.5707963267949 0.0 0.0" xyz="0 -0.4 0"/>
      <geometry>
        <mesh filename="package://ur_e_description/meshes/ur5e/dual_ur5_base.stl"/>
      </geometry>
    </collision>
    <inertial>
      <mass value="1000"/>
      <origin rpy="0 0 0" xyz="0.0 0.0 0.8"/>
      <inertia ixx="1.0" ixy="0.0" ixz="0.0" iyy="1.0" iyz="0.0" izz="1.0"/>
    </inertial>
  </link>
  <joint name="base_to_fixed" type="fixed">
    <parent link="dual_arm_base"/>
    <child link="fixed_base"/>
    <origin rpy="0.0 0.0 0.0" xyz="0.04 0.0 1.44"/>
  </joint>
  <link name="table_plane">
    <visual>
      <origin xyz="0.3 0 0.01"/>
      <geometry>
        <box size="0.6 1.2 0.02"/>
      </geometry>
      <material name="table">
        <color rgba="0.7 0.6 0.5 1.0"/>
      </material>
    </visual>
    <collision>
      <origin xyz="0.3 0 0.01"/>
      <geometry>
        <box size="0.6 1.2 0.02"/>
      </geometry>
    </collision>
  </link>
  <link name="controller_plane0">
    <visual>
      <origin xyz="0.3 0 0.01"/>
      <geometry>
        <box size="0.6 0.8 0.02"/>
      </geometry>
      <material name="plane">
        <color rgba="0.6 0.6 0.6 1.0"/>
      </material>
    </visual>
  </link>
  <link name="controller_plane1">
    <visual>
      <origin xyz="0.3 0 0.01"/>
      <geometry>
        <box size="0.6 0.8 0.02"/>
      </geometry>
      <material name="plane"/>
    </visual>
  </link>
  <joint name="base_to_table_plane" type="fixed">
    <parent link="dual_arm_base"/>
    <child link="table_plane"/>
    <origin rpy="0.0 0.0 0.0" xyz="0.0 0.0 0.8"/>
  </joint>
  <joint name="base_to_c_plane0" type="fixed">
    <parent link="dual_arm_base"/>
    <child link="controller_plane0"/>
    <origin rpy="0.0 0.0 0.0" xyz="0.0 0.0 0.2"/>
  </joint>
  <joint name="base_to_c_plane1" type="fixed">
    <parent link="dual_arm_base"/>
    <child link="controller_plane1"/>
    <origin rpy="0.0 0.0 0.0" xyz="0.0 0.0 0.5"/>
  </joint>
  <link name="controller0">
    <visual>
      <origin xyz="0.3 0 0.134"/>
      <geometry>
        <box size="0.475 0.423 0.268"/>
      </geometry>
      <material name="controller">
        <color rgba="0.5 0.5 0.6 1.0"/>
      </material>
    </visual>
  </link>
  <link name="controller1">
    <visual>
      <origin xyz="0.3 0 0.134"/>
      <geometry>
        <box size="0.475 0.423 0.268"/>
      </geometry>
      <material name="controller"/>
    </visual>
  </link>
  <joint name="base_to_c0" type="fixed">
    <parent link="dual_arm_base"/>
    <child link="controller0"/>
    <origin rpy="0.0 0.0 0.0" xyz="0.0 0.0 0.22"/>
  </joint>
  <joint name="base_to_c1" type="fixed">
    <parent link="dual_arm_base"/>
    <child link="controller1"/>
    <origin rpy="0.0 0.0 0.0" xyz="0.0 0.0 0.52"/>
  </joint>
  <link name="dual_arm_booth">
    <visual>
      <origin rpy="1.5707963267949 0.0 0.0" xyz="0 -0.75 0"/>
      <geometry>
        <mesh filename="package://ur_e_description/meshes/ur5e/dual_ur5_booth.stl" scale="0.001 0.001 0.001"/>
      </geometry>
      <material name="misumi">
        <color rgba="0.75 0.75 0.75 1.0"/>
      </material>
    </visual>
    <collision>
      <origin rpy="1.5707963267949 0.0 0.0" xyz="0 -0.75 0"/>
      <geometry>
        <mesh filename="package://ur_e_description/meshes/ur5e/dual_ur5_booth.stl" scale="0.001 0.001 0.001"/>
      </geometry>
    </collision>
    <inertial>
      <mass value="1000"/>
      <origin rpy="0 0 0" xyz="0.0 0.0 0.8"/>
      <inertia ixx="1.0" ixy="0.0" ixz="0.0" iyy="1.0" iyz="0.0" izz="1.0"/>
    </inertial>
  </link>
  <joint name="base_to_booth" type="fixed">
    <parent link="dual_arm_base"/>
    <child link="dual_arm_booth"/>
    <origin rpy="0.0 0.0 0.0" xyz="-0.11 0.0 0.0"/>
  </joint>
  <link name="display">
    <visual>
      <geometry>
        <box size="0.03 0.817 0.342"/>
      </geometry>
      <material name="Display">
        <color rgba="0.15 0.15 0.15 1.0"/>
      </material>
    </visual>
    <collision>
      <geometry>
        <box size="0.03 0.817 0.342"/>
      </geometry>
    </collision>
  </link>
  <joint name="base_to_dispaly" type="fixed">
    <parent link="dual_arm_base"/>
    <child link="display"/>
    <origin rpy="0.0 0.2 0.0" xyz="0.0 0.0 1.72"/>
  </joint>
  <!--xacro:include filename="$(find openni_description)/model/kinect.urdf.xacro" /-->
  <gazebo reference="pan_tilt_BASE">
    <mu1>0.9</mu1>
    <mu2>0.9</mu2>
  </gazebo>
  <link name="pan_tilt_BASE">
    <inertial>
      <mass value="0.112"/>
      <origin rpy="0 0 0" xyz="-2.187035e-19 -0.012536 -0.000367"/>
      <inertia ixx="3.737235e-05" ixy="-1.093518e-22" ixz="-1.117885e-21" iyy="2.575474e-05" iyz="-9.334821e-07" izz="2.726761e-05"/>
    </inertial>
    <visual>
      <origin rpy="0.00000000 -0.00000000 0.00000000" xyz="0.000000 0.000000 0.000000"/>
      <geometry>
        <mesh filename="package://ur_e_description/pan_tilt/meshes/xm430_dynamixel.dae" scale="1.000000 1.000000 1.000000"/>
      </geometry>
    </visual>
    <collision>
      <origin rpy="0.00000000 -0.00000000 0.00000000" xyz="0.000000 0.000000 0.000000"/>
      <geometry>
        <mesh filename="package://ur_e_description/pan_tilt/meshes/xm430_dynamixel.dae" scale="1.000000 1.000000 1.000000"/>
      </geometry>
    </collision>
    <visual>
      <origin rpy="-1.57079633 0.00000000 3.14159265" xyz="-0.000000 -0.000000 -0.003000"/>
      <geometry>
        <mesh filename="package://ur_e_description/pan_tilt/meshes/fr12_x102.dae" scale="1.000000 1.000000 1.000000"/>
      </geometry>
    </visual>
    <collision>
      <origin rpy="-1.57079633 0.00000000 3.14159265" xyz="-0.000000 -0.000000 -0.003000"/>
      <geometry>
        <mesh filename="package://ur_e_description/pan_tilt/meshes/fr12_x102.dae" scale="1.000000 1.000000 1.000000"/>
      </geometry>
    </collision>
  </link>
  <gazebo reference="pan_tilt_LINK0">
    <mu1>0.9</mu1>
    <mu2>0.9</mu2>
  </gazebo>
  <link name="pan_tilt_LINK0">
    <inertial>
      <mass value="0.015"/>
      <origin rpy="0 0 0" xyz="0.0 0.01345 -0.019"/>
      <inertia ixx="1.969763e-06" ixy="0.0" ixz="0.0" iyy="3.012500e-06" iyz="9.466331e-38" izz="3.159763e-06"/>
    </inertial>
    <visual>
      <origin rpy="0.00000000 1.57079633 0.00000000" xyz="0.000000 0.000000 -0.019000"/>
      <geometry>
        <mesh filename="package://ur_e_description/pan_tilt/meshes/fr12_h101s.dae" scale="1.000000 1.000000 1.000000"/>
      </geometry>
    </visual>
    <collision>
      <origin rpy="0.00000000 1.57079633 0.00000000" xyz="0.000000 0.000000 -0.019000"/>
      <geometry>
        <mesh filename="package://ur_e_description/pan_tilt/meshes/fr12_h101s.dae" scale="1.000000 1.000000 1.000000"/>
      </geometry>
    </collision>
  </link>
  <transmission name="pan_tilt_JOINT0_trans">
    <type>transmission_interface/SimpleTransmission</type>
    <joint name="pan_tilt_JOINT0">
      <hardwareInterface>hardware_interface/VelocityJointInterface</hardwareInterface>
      <!--hardwareInterface>hardware_interface/EffortJointInterface</hardwareInterface-->
    </joint>
    <actuator name="pan_tilt_JOINT0_motor">
      <hardwareInterface>hardware_interface/VelocityJointInterface</hardwareInterface>
      <!--hardwareInterface>hardware_interface/EffortJointInterface</hardwareInterface-->
      <mechanicalReduction>1</mechanicalReduction>
    </actuator>
  </transmission>
  <joint name="pan_tilt_JOINT0" type="revolute">
    <parent link="pan_tilt_BASE"/>
    <child link="pan_tilt_LINK0"/>
    <origin rpy="0.00000000 -0.00000000 0.00000000" xyz="0.000000 0.000000 0.019000"/>
    <axis xyz="0 0 1"/>
    <limit effort="200" lower="-3.14159" upper="3.14159" velocity="40"/>
  </joint>
  <gazebo reference="pan_tilt_BASE">
    <mu1>0.9</mu1>
    <mu2>0.9</mu2>
  </gazebo>
  <link name="pan_tilt_PAN_BASE">
    <inertial>
      <mass value="0.1"/>
      <origin rpy="0 0 0" xyz="0.0 -0.012 0.0015"/>
      <inertia ixx="3.202708e-05" ixy="0.0" ixz="0.0" iyy="2.077708e-05" iyz="3.549874e-37" izz="2.478750e-05"/>
    </inertial>
    <visual>
      <origin rpy="0.00000000 -0.00000000 0.00000000" xyz="0.000000 0.000000 0.000000"/>
      <geometry>
        <mesh filename="package://ur_e_description/pan_tilt/meshes/xm430_dynamixel.dae" scale="1.000000 1.000000 1.000000"/>
      </geometry>
    </visual>
    <collision>
      <origin rpy="0.00000000 -0.00000000 0.00000000" xyz="0.000000 0.000000 0.000000"/>
      <geometry>
        <mesh filename="package://ur_e_description/pan_tilt/meshes/xm430_dynamixel.dae" scale="1.000000 1.000000 1.000000"/>
      </geometry>
    </collision>
  </link>
  <gazebo reference="pan_tilt_LINK1">
    <mu1>0.9</mu1>
    <mu2>0.9</mu2>
  </gazebo>
  <link name="pan_tilt_LINK1">
    <inertial>
      <mass value="0.015"/>
      <origin rpy="0 0 0" xyz="-0.01345 9.706125e-18 -0.019"/>
      <inertia ixx="3.012500e-06" ixy="-7.524859e-22" ixz="-9.466331e-38" iyy="1.969763e-06" iyz="8.407791e-53" izz="3.159763e-06"/>
    </inertial>
    <visual>
      <origin rpy="0.00000000 1.57079633 1.57079633" xyz="0.000000 0.000000 -0.019000"/>
      <geometry>
        <mesh filename="package://ur_e_description/pan_tilt/meshes/fr12_h101.dae" scale="1.000000 1.000000 1.000000"/>
      </geometry>
    </visual>
    <collision>
      <origin rpy="0.00000000 1.57079633 1.57079633" xyz="0.000000 0.000000 -0.019000"/>
      <geometry>
        <mesh filename="package://ur_e_description/pan_tilt/meshes/fr12_h101.dae" scale="1.000000 1.000000 1.000000"/>
      </geometry>
    </collision>
  </link>
  <transmission name="pan_tilt_JOINT1_trans">
    <type>transmission_interface/SimpleTransmission</type>
    <joint name="pan_tilt_JOINT1">
      <hardwareInterface>hardware_interface/VelocityJointInterface</hardwareInterface>
      <!--hardwareInterface>hardware_interface/EffortJointInterface</hardwareInterface-->
    </joint>
    <actuator name="pan_tilt_JOINT1_motor">
      <hardwareInterface>hardware_interface/VelocityJointInterface</hardwareInterface>
      <!--hardwareInterface>hardware_interface/EffortJointInterface</hardwareInterface-->
      <mechanicalReduction>1</mechanicalReduction>
    </actuator>
  </transmission>
  <joint name="pan_tilt_JOINT1" type="revolute">
    <parent link="pan_tilt_PAN_BASE"/>
    <child link="pan_tilt_LINK1"/>
    <origin rpy="0.00000000 -0.00000000 0.00000000" xyz="0.000000 0.000000 0.019000"/>
    <axis xyz="0 0 1"/>
    <limit effort="200" lower="-3.14159" upper="3.14159" velocity="40"/>
  </joint>
  <joint name="pan_tilt_tilt_to_pan" type="fixed">
    <parent link="pan_tilt_LINK0"/>
    <child link="pan_tilt_PAN_BASE"/>
    <origin rpy="0.0 1.57079633 0.0" xyz="0.0 0.0 0.016"/>
  </joint>
  <joint name="camera_rgb_joint" type="fixed">
    <origin rpy="-1.57079633 0.0 1.57079633" xyz="-0.08 0.03 -0.045"/>
    <parent link="pan_tilt_LINK1"/>
    <child link="camera_rgb_frame"/>
  </joint>
  <link name="camera_rgb_frame"/>
  <joint name="camera_rgb_optical_joint" type="fixed">
    <origin rpy="-1.57079632679 0 -1.57079632679" xyz="0 0 0"/>
    <parent link="camera_rgb_frame"/>
    <child link="camera_rgb_optical_frame"/>
  </joint>
  <link name="camera_rgb_optical_frame"/>
  <joint name="camera_joint" type="fixed">
    <origin rpy="0 0 0" xyz="-0.031 -0.03 -0.016"/>
    <parent link="camera_rgb_frame"/>
    <child link="camera_link"/>
  </joint>
  <link name="camera_link">
    <visual>
      <origin rpy="0 0 1.57079632679" xyz="0 0 0"/>
      <geometry>
        <mesh filename="package://ur_e_description/pan_tilt/meshes/kinect.dae"/>
      </geometry>
    </visual>
    <collision>
      <origin rpy="0 0 0" xyz="0.0 0.0 0.0"/>
      <geometry>
        <box size="0.07271 0.27794 0.073"/>
      </geometry>
    </collision>
    <inertial>
      <mass value="0.564"/>
      <origin xyz="0 0 0"/>
      <inertia ixx="0.003881243" ixy="0.0" ixz="0.0" iyy="0.000498940" iyz="0.0" izz="0.003879257"/>
    </inertial>
  </link>
  <!-- The fixed joints & links below are usually published by static_transformers launched by the OpenNi launch 
         files. However, for Gazebo simulation we need them, so we add them here.
         (Hence, don't publish them additionally!) -->
  <joint name="camera_depth_joint" type="fixed">
    <origin rpy="0 0 0" xyz="0 -0.06 0"/>
    <parent link="camera_rgb_frame"/>
    <child link="camera_depth_frame"/>
  </joint>
  <link name="camera_depth_frame"/>
  <joint name="camera_depth_optical_joint" type="fixed">
    <origin rpy="-1.57079632679 0 -1.57079632679" xyz="0 0 0"/>
    <parent link="camera_depth_frame"/>
    <child link="camera_depth_optical_frame"/>
  </joint>
  <link name="camera_depth_optical_frame"/>
  <gazebo reference="camera_link">
    <sensor name="camera" type="depth">
      <always_on>true</always_on>
      <update_rate>20.0</update_rate>
      <camera>
        <horizontal_fov>1.0471975512</horizontal_fov>
        <image>
          <format>B8G8R8</format>
          <width>640</width>
          <height>480</height>
        </image>
        <clip>
          <near>0.05</near>
          <far>8.0</far>
        </clip>
      </camera>
      <plugin filename="libgazebo_ros_openni_kinect.so" name="kinect_camera_controller">
        <cameraName>camera</cameraName>
        <alwaysOn>true</alwaysOn>
        <updateRate>10</updateRate>
        <imageTopicName>rgb/image_raw</imageTopicName>
        <depthImageTopicName>depth/image_raw</depthImageTopicName>
        <pointCloudTopicName>depth/points</pointCloudTopicName>
        <cameraInfoTopicName>rgb/camera_info</cameraInfoTopicName>
        <depthImageCameraInfoTopicName>depth/camera_info</depthImageCameraInfoTopicName>
        <frameName>camera_depth_optical_frame</frameName>
        <baseline>0.1</baseline>
        <distortion_k1>0.0</distortion_k1>
        <distortion_k2>0.0</distortion_k2>
        <distortion_k3>0.0</distortion_k3>
        <distortion_t1>0.0</distortion_t1>
        <distortion_t2>0.0</distortion_t2>
        <pointCloudCutoff>0.4</pointCloudCutoff>
      </plugin>
    </sensor>
  </gazebo>
  <joint name="" type="fixed">
    <parent link="dual_arm_base"/>
    <child link="pan_tilt_BASE"/>
    <origin rpy="0.0 0.0 -1.5707963267949" xyz="0.08 0.0 1.505"/>
  </joint>
  <!-- hand -->
  <link name="lhand">
    <visual>
      <geometry>
        <mesh filename="package://ur_e_description/meshes/RG6Gripper.stl"/>
      </geometry>
      <material name="Gripper">
        <color rgba="0.10 0.10 0.20 1.0"/>
      </material>
    </visual>
    <collision>
      <geometry>
        <mesh filename="package://ur_e_description/meshes/RG6Gripper.stl"/>
      </geometry>
    </collision>
  </link>
  <joint name="larm_to_lhand" type="fixed">
    <parent link="left_wrist_3_link"/>
    <child link="lhand"/>
    <!--origin rpy="1.5707963267949 0.0 -1.5707963267949" xyz="0.025 0.120 0.0"/-->
    <!-- side -->
    <origin rpy="1.5707963267949 0.0 3.14159265358979" xyz="0.0 0.105 0.0"/>
    <!-- up/down -->
  </joint>
  <link name="rhand">
    <visual>
      <geometry>
        <mesh filename="package://ur_e_description/meshes/RG6Gripper.stl"/>
      </geometry>
      <material name="Gripper"/>
    </visual>
    <collision>
      <geometry>
        <mesh filename="package://ur_e_description/meshes/RG6Gripper.stl"/>
      </geometry>
    </collision>
  </link>
  <joint name="rarm_to_rhand" type="fixed">
    <parent link="right_wrist_3_link"/>
    <child link="rhand"/>
    <origin rpy="1.5707963267949 0.0 1.5707963267949" xyz="-0.025 0.120 0.0"/>
    <!-- side -->
    <!--origin rpy="1.5707963267949 0.0 3.14159265358979" xyz="0.0 0.105 0.0"/-->
    <!-- up/down -->
  </joint>
</robot>

